<?xml version='1.0'?>

<robot name="my_robot" xmlns:xacro="http://www.ros.org/wiki/xacro">

  <xacro:include filename="$(find my_robot)/urdf/my_robot.gazebo" />

  <material name="red">
    <color rgba= "${169/255} 0 0 1"/>
  </material>
  <material name="black">
    <color rgba="0 0 0 1"/>
  </material>


  <link name="robot_footprint"></link>

  <joint name="robot_footprint_joint" type="fixed">
    <origin xyz="0 0 0" rpy="0 0 0" />
    <parent link="robot_footprint"/>
    <child link="chassis" />
  </joint>

  <link name='chassis'>
    <pose>0 0 0.1 0 0 0</pose>

    <inertial>
      <mass value="10.0"/>
      <origin xyz="0.0 0 0" rpy=" 0 0 0"/>
      <inertia
          ixx="0.0975" ixy="0" ixz="0"
          iyy="0.0975" iyz="0"
          izz="0.0975"
      />
    </inertial>

    <collision name='collision'>
      <origin xyz="0 0 0" rpy=" 0 0 0"/> 
      <geometry>
        <box size=".5 .3 .2"/>
      </geometry>
    </collision>

    <visual name='chassis_visual'>
      <origin xyz="0 0 0" rpy=" 0 0 0"/>
      <geometry>
        <box size=".5 .3 .2"/>
      </geometry>
      <material name="red"/>
    </visual>
  </link>

  <joint name="back_caster_join" type="fixed">
    <origin xyz="-0.2 0.0 -0.1" rpy="0.0 0.0 0.0"/>
    <parent link="chassis"/>
    <child link="back_caster"/>
  </joint>

  <link name="back_caster">

    <inertial>
      <origin xyz="0.0 0.0 0.0" rpy="0.0 0.0 0.0"/>
      <mass value="2.5"/>
      <inertia ixx="0.0025" ixy="0.0" ixz="0.0" iyy="0.0025" iyz="0.0" izz="0.0025"/>
    </inertial>
    
    <collision name='back_caster_collision'>
      <origin xyz="0 0 0" rpy=" 0 0 0"/>
      <geometry>
        <sphere radius="0.05"/>
      </geometry>
      <surface>
        <friction>
          <ode>
            <mu>0.00001</mu>
            <mu2>0.00001</mu2>
          </ode>
        </friction>
      </surface>
    </collision>

    <visual name='back_caster_visual'>
      <origin xyz="0 0 0" rpy=" 0 0 0"/>
      <geometry>
        <sphere radius="0.05"/>
      </geometry>
      <material name="black"/>
    </visual>
  </link>

  <joint name="front_caster_join" type="fixed">
    <origin xyz="0.2 0.0 -0.1" rpy="0.0 0.0 0.0"/>
    <parent link="chassis"/>
    <child link="front_caster"/>
  </joint>

  <link name="front_caster">

    <inertial>
      <origin xyz="0.0 0.0 0.0" rpy="0.0 0.0 0.0"/>
      <mass value="2.5"/>
      <inertia ixx="0.0025" ixy="0.0" ixz="0.0" iyy="0.0025" iyz="0.0" izz="0.0025"/>
    </inertial>

    <collision name='front_caster_collision'>
      <origin xyz="0 0 0" rpy=" 0 0 0"/>
      <geometry>
        <sphere radius="0.05"/>
      </geometry>
      <surface>
        <friction>
          <ode>
            <mu>0.00001</mu>
            <mu2>0.00001</mu2>
          </ode>
        </friction>
      </surface>
    </collision>

    <visual name='front_caster_visual'>
      <origin xyz="0 0 0" rpy=" 0 0 0"/>
      <geometry>
        <sphere radius="0.05"/>
      </geometry>
      <material name="black"/>
    </visual>

  </link>

  <joint type="continuous" name="left_wheel_hinge">
    <origin xyz="0 0.17 0" rpy="0 0 0"/>
    <child link="left_wheel"/>
    <parent link="chassis"/>
    <axis xyz="0 1 0" rpy="0 0 0"/>
    <limit effort="10000" velocity="1000"/>
    <dynamics damping="1.0" friction="1.0"/>
  </joint>

  <!-- <link name='left_wheel'>

    <inertial name='left_wheel_inertial'>
      <origin xyz="0 0 0" rpy="0 1.5707 1.5707"/>
      <mass value="5"/>
      <inertia ixx="0.1" ixy="0" ixz="0" iyy="0.1" iyz="0" izz="0.1"/>
    </inertial>

    <collision name='left_wheel_collision'>
      <origin xyz="0 0 0" rpy="0 1.5707 1.5707"/>
      <geometry>
        <cylinder radius="0.15" length="0.05"/>
      </geometry>
    </collision>

    <visual name='left_wheel_visual'>
      <origin xyz="0 0 0" rpy="0 1.5707 1.5707"/>
      <geometry>
        <cylinder radius="0.15" length="0.05"/>
      </geometry>
    </visual>
    
  </link> -->

  <link name="left_wheel">
    <inertial name='left_wheel_inertial'>
      <origin xyz="0 0 0" rpy="0 1.5707 1.5707"/>
      <mass value="5"/>
      <inertia ixx="0.1" ixy="0" ixz="0" iyy="0.1" iyz="0" izz="0.1"/>
    </inertial>
    <collision name="collision">
      <origin xyz="0 0 0" rpy="0 1.5707 1.5707"/>
      <geometry>
        <cylinder radius="0.15" length="0.05"/>
      </geometry>
      <!-- <surface>
        <friction>
          <ode>
            <mu>1.0</mu>
            <mu2>1.0</mu2>
            <fdir1>0 0 1</fdir1>
            <slip1>0.0</slip1>
            <slip2>0.0</slip2>
          </ode>
        </friction>
        <contact>
          <ode>
            <min_depth>0.005</min_depth>
            <kp>1e8</kp>
          </ode>
        </contact>
      </surface> -->
    </collision>
    <visual name="visual">
      <origin xyz="0 0 0" rpy="0 1.5707 1.5707"/>
      <geometry>
        <mesh scale="0.68 0.68 0.5" filename="package://my_robot/models/wheel/meshes/wheel.dae"/>
      </geometry>
    </visual>
  </link>

  <joint type="continuous" name="right_wheel_hinge">
    <origin xyz="0 -0.17 0" rpy="0 0 0"/>
    <child link="right_wheel"/>
    <parent link="chassis"/>
    <axis xyz="0 1 0" rpy="0 0 0"/>
    <limit effort="10000" velocity="1000"/>
    <dynamics damping="1.0" friction="1.0"/>
  </joint>

  <link name="right_wheel">
    <inertial name='right_wheel_inertial'>
      <origin xyz="0 0 0" rpy="0 -1.5707 1.5707"/>
      <mass value="5"/>
      <inertia ixx="0.1" ixy="0" ixz="0" iyy="0.1" iyz="0" izz="0.1"/>
    </inertial>
    <collision name="collision">
      <origin xyz="0 0 0" rpy="0 -1.5707 1.5707"/>
      <geometry>
        <cylinder radius="0.15" length="0.05"/>
      </geometry>
      <!-- <surface>
        <friction>
          <ode>
            <mu>1.0</mu>
            <mu2>1.0</mu2>
            <fdir1>0 0 1</fdir1>
            <slip1>0.0</slip1>
            <slip2>0.0</slip2>
          </ode>
        </friction>
        <contact>
          <ode>
            <min_depth>0.005</min_depth>
            <kp>1e8</kp>
          </ode>
        </contact>
      </surface> -->
    </collision>
    <visual name="visual">
      <origin xyz="0 0 0" rpy="0 -1.5707 1.5707"/>
      <geometry>
        <mesh scale="0.68 0.68 0.5" filename="package://my_robot/models/wheel/meshes/wheel.dae"/>
      </geometry>
    </visual>
  </link>

  <joint name="camera_join" type="fixed">
    <origin xyz="0.25 0.0 0.0" rpy="0.0 0.0 0.0"/>
    <parent link="chassis"/>
    <child link="camera"/>
    <axis xyz="0.0 1 0.0"/>
  </joint>
  
  <link name="camera">

    <inertial>
      <mass value="0.1"/>
      <inertia ixx="1e-6" ixy="0.0" ixz="0.0" iyy="1e-6" iyz="0.0" izz="1e-6"/>
    </inertial>

    <visual>
      <origin xyz="0 0 0" rpy="0 0 0"/>
      <geometry>
        <box size="0.05 0.05 0.05"/>
      </geometry>
      <material name="black"/>
    </visual>

    <collision>
      <origin xyz="0 0 0" rpy="0 0 0"/>
      <geometry>
        <box size="0.05 0.05 0.05"/>
      </geometry>
    </collision>
    
  </link>

  <link name="hokuyo">

    <inertial>
      <origin xyz="0.0 0.0 0.0" rpy="0.0 0.0 0.0"/>
      <mass value="1e-5"/>
      <inertia ixx="1e-6" ixy="0.0" ixz="0.0" iyy="1e-6" iyz="0.0" izz="1e-6"/>
    </inertial>

    <visual>
      <origin xyz="0.0 0.0 0.0" rpy="0.0 0.0 0.0"/>
      <geometry>
        <mesh filename="package://my_robot/meshes/hokuyo.dae"/>
      </geometry>
    </visual>

    <collision>
      <origin xyz="0.0 0.0 0.0" rpy="0.0 0.0 0.0"/>
      <geometry>
        <box size="0.1 0.1 0.1"/>
      </geometry>
    </collision>

  </link>

  <joint name="hokuyo_joint" type="fixed">
    <origin xyz="0.2 0.0 0.125" rpy="0.0 0.0 0.0"/>
    <parent link="chassis"/>
    <child link="hokuyo"/>
    <axis xyz="0.0 1 0.0"/>
  </joint>

  <gazebo reference="camera"> 
    <material>Gazebo/Black</material> 
  </gazebo> 
  <gazebo reference="chassis"> 
    <material>Gazebo/Red</material> 
  </gazebo> 
  <gazebo reference="back_caster"> 
    <material>Gazebo/Black</material> 
  </gazebo> 
  <gazebo reference="front_caster"> 
    <material>Gazebo/Black</material> 
  </gazebo> 
</robot>